2024-04-10 21:25:40.823065: I external/local_tsl/tsl/cuda/cudart_stub.cc:32] Could not find cuda drivers on your machine, GPU will not be used.
2024-04-10 21:25:43.417331: I external/local_tsl/tsl/cuda/cudart_stub.cc:32] Could not find cuda drivers on your machine, GPU will not be used.
2024-04-10 21:25:54.175551: I tensorflow/core/platform/cpu_feature_guard.cc:210] This TensorFlow binary is optimized to use available CPU instructions in performance-critical operations.
To enable the following instructions: AVX2 FMA, in other operations, rebuild TensorFlow with the appropriate compiler flags.
2024-04-10 21:26:07.521896: W tensorflow/compiler/tf2tensorrt/utils/py_utils.cc:38] TF-TRT Warning: Could not find TensorRT
Traceback (most recent call last):
  File "/afs/cern.ch/work/t/tcritchl/FCCAnalyses_local/DNN/DNN_condor/test_evaluate_model.py", line 76, in <module>
    test_loss, test_acc = model.evaluate(X_test, y_test, verbose=2)
  File "/afs/cern.ch/work/t/tcritchl/FCCAnalyses_local/DNN/venv/lib/python3.10/site-packages/keras/src/utils/traceback_utils.py", line 122, in error_handler
    raise e.with_traceback(filtered_tb) from None
  File "/afs/cern.ch/work/t/tcritchl/FCCAnalyses_local/DNN/venv/lib/python3.10/site-packages/keras/src/layers/input_spec.py", line 227, in assert_input_compatibility
    raise ValueError(
ValueError: Exception encountered when calling Sequential.call().

[1mInput 0 of layer "dense" is incompatible with the layer: expected axis -1 of input shape to have value 10, but received input with shape (None, 13)[0m

Arguments received by Sequential.call():
  â€¢ inputs=tf.Tensor(shape=(None, 13), dtype=float32)
  â€¢ training=False
  â€¢ mask=None
