Error in <TFile::TFile>: no read permission, could not open file /eos/user/p/pakontax/FCC_8March2024/p8_ee_Zbb_ecm91/chunk_1183.root
Traceback (most recent call last):
  File "/afs/cern.ch/work/t/tcritchl/FCCAnalyses_local/xgboost/new_variables_training/training_macro.py", line 194, in <module>
    json.dump(results_dict, f, indent=4)
  File "/cvmfs/sft.cern.ch/lcg/releases/Python/3.9.12-9a1bc/x86_64-centos7-gcc11-opt/lib/python3.9/json/__init__.py", line 179, in dump
    for chunk in iterable:
  File "/cvmfs/sft.cern.ch/lcg/releases/Python/3.9.12-9a1bc/x86_64-centos7-gcc11-opt/lib/python3.9/json/encoder.py", line 431, in _iterencode
    yield from _iterencode_dict(o, _current_indent_level)
  File "/cvmfs/sft.cern.ch/lcg/releases/Python/3.9.12-9a1bc/x86_64-centos7-gcc11-opt/lib/python3.9/json/encoder.py", line 405, in _iterencode_dict
    yield from chunks
  File "/cvmfs/sft.cern.ch/lcg/releases/Python/3.9.12-9a1bc/x86_64-centos7-gcc11-opt/lib/python3.9/json/encoder.py", line 405, in _iterencode_dict
    yield from chunks
  File "/cvmfs/sft.cern.ch/lcg/releases/Python/3.9.12-9a1bc/x86_64-centos7-gcc11-opt/lib/python3.9/json/encoder.py", line 438, in _iterencode
    o = _default(o)
  File "/cvmfs/sft.cern.ch/lcg/releases/Python/3.9.12-9a1bc/x86_64-centos7-gcc11-opt/lib/python3.9/json/encoder.py", line 179, in default
    raise TypeError(f'Object of type {o.__class__.__name__} '
TypeError: Object of type float32 is not JSON serializable
