Error in <TFile::TFile>: no read permission, could not open file /eos/user/t/tcritchl/xgBOOST/fullstats/withvertex/p8_ee_Zcc_ecm91/chunk_1159.root
Traceback (most recent call last):
  File "/afs/cern.ch/work/t/tcritchl/FCCAnalyses_local/xgboost/new_variables_training/20GEV_filter/testing_macro.py", line 2, in <module>
    from training_macro import load_data
  File "/cvmfs/sft-nightlies.cern.ch/lcg/views/dev3/Mon/x86_64-centos7-gcc11-opt/lib/ROOT/_facade.py", line 154, in _importhook
    return _orig_ihook(name, *args, **kwds)
  File "/afs/cern.ch/work/t/tcritchl/FCCAnalyses_local/xgboost/new_variables_training/20GEV_filter/training_macro.py", line 10, in <module>
    from DataPreparation_macro import masses, couplings, variables
  File "/cvmfs/sft-nightlies.cern.ch/lcg/views/dev3/Mon/x86_64-centos7-gcc11-opt/lib/ROOT/_facade.py", line 154, in _importhook
    return _orig_ihook(name, *args, **kwds)
  File "/afs/cern.ch/work/t/tcritchl/FCCAnalyses_local/xgboost/new_variables_training/20GEV_filter/DataPreparation_macro.py", line 108, in <module>
    for chunk_file in os.listdir(bg_dir):
FileNotFoundError: [Errno 2] No such file or directory: '/eos/user/t/tcritchl/xgBOOST/fullstats/withvertex/ejjnu/'
