2024-04-03 09:43:19.176414: I external/local_tsl/tsl/cuda/cudart_stub.cc:32] Could not find cuda drivers on your machine, GPU will not be used.
2024-04-03 09:43:29.011749: I external/local_tsl/tsl/cuda/cudart_stub.cc:32] Could not find cuda drivers on your machine, GPU will not be used.
2024-04-03 09:43:56.836880: I tensorflow/core/platform/cpu_feature_guard.cc:210] This TensorFlow binary is optimized to use available CPU instructions in performance-critical operations.
To enable the following instructions: AVX2 FMA, in other operations, rebuild TensorFlow with the appropriate compiler flags.
2024-04-03 09:44:12.262722: W tensorflow/compiler/tf2tensorrt/utils/py_utils.cc:38] TF-TRT Warning: Could not find TensorRT
/afs/cern.ch/work/t/tcritchl/FCCAnalyses_local/DNN/venv/lib/python3.10/site-packages/sklearn/metrics/_ranking.py:1124: UndefinedMetricWarning: No negative samples in y_true, false positive value should be meaningless
  warnings.warn(
2024-04-03 09:44:45.550955: W tensorflow/core/framework/local_rendezvous.cc:404] Local rendezvous is aborting with status: OUT_OF_RANGE: End of sequence
/cvmfs/sw.hsf.org/key4hep/releases/2024-03-10/x86_64-centos7-gcc12.2.0-opt/python/3.10.13-75qggg/lib/python3.10/contextlib.py:153: UserWarning: Your input ran out of data; interrupting training. Make sure that your dataset or generator can generate at least `steps_per_epoch * epochs` batches. You may need to use the `.repeat()` function when building your dataset.
  self.gen.throw(typ, value, traceback)
Traceback (most recent call last):
  File "/afs/cern.ch/work/t/tcritchl/FCCAnalyses_local/DNN/DNN_condor/test_evaluate_model.py", line 104, in <module>
    y_pred_background = model.predict(X_test[y_test == 0]).ravel()
  File "/afs/cern.ch/work/t/tcritchl/FCCAnalyses_local/DNN/venv/lib/python3.10/site-packages/keras/src/utils/traceback_utils.py", line 122, in error_handler
    raise e.with_traceback(filtered_tb) from None
  File "/afs/cern.ch/work/t/tcritchl/FCCAnalyses_local/DNN/venv/lib/python3.10/site-packages/keras/src/utils/progbar.py", line 119, in update
    numdigits = int(math.log10(self.target)) + 1
ValueError: math domain error
